#VRML_SIM R2020a utf8
WorldInfo {
}
Viewpoint {
  orientation -0.03432234506676366 0.9811367695180863 0.19024357053191523 2.7590946438124937
  position -1.0138297289930176 0.31125577760190953 0.6897009711926096
}
TexturedBackground {
}
TexturedBackgroundLight {
}
RectangleArena {
  floorSize 3.5 3.5
  wallThickness 0.02
  wallHeight 0.3
}
Robot {
  translation -1.23138 0.0397206 1.28743
  rotation 3.9115399986248e-06 0.9999999996484248 -2.6226899990779272e-05 2.84664
  children [
    GPS {
    }
    Camera {
      translation 0 0.03 0.085
      rotation 0 1 0 3.14159
      children [
        Shape {
          appearance PBRAppearance {
            baseColor 0 0 0
          }
          geometry Box {
            size 0.04 0.01 0.01
          }
        }
      ]
      name "camera0"
      width 100
      height 100
    }
    DEF BODY Shape {
      appearance PBRAppearance {
        baseColor 0.678431 0.498039 0.658824
        roughness 1
        metalness 0
      }
      geometry Box {
        size 0.1 0.05 0.2
      }
    }
    DEF TL_WHEEL HingeJoint {
      jointParameters HingeJointParameters {
        position 179.2639344653845
        anchor 0.06 0 0.05
      }
      device [
        RotationalMotor {
          name "tl_wheel"
        }
      ]
      endPoint Solid {
        translation 0.059999999603073784 -2.854417133031882e-06 0.05000269263808757
        rotation -0.7059329956090293 0.7059355887073492 0.057563445925957156 3.0265930907113714
        children [
          DEF WHEEL Shape {
            appearance PBRAppearance {
              baseColor 0.203922 0.396078 0.643137
              roughness 1
              metalness 0
            }
            geometry Cylinder {
              height 0.02
              radius 0.04
              subdivision 24
            }
          }
        ]
        boundingObject USE WHEEL
        physics Physics {
        }
      }
    }
    DEF TR_WHEEL HingeJoint {
      jointParameters HingeJointParameters {
        position 170.88006209110733
        anchor -0.06 0 0.05
      }
      device [
        RotationalMotor {
          name "trwheel"
        }
      ]
      endPoint Solid {
        translation -0.0600000003974106 3.5958543799533063e-06 0.04999842920827169
        rotation -0.49332930443252027 0.49333111663075296 -0.7164151078473848 4.384905315914677
        children [
          USE WHEEL
        ]
        name "solid(1)"
        boundingObject USE WHEEL
        physics Physics {
        }
      }
    }
    DEF BL_WHEEL HingeJoint {
      jointParameters HingeJointParameters {
        position 179.26393786552165
        anchor 0.06 0 -0.05
      }
      device [
        RotationalMotor {
          name "blwheel"
        }
      ]
      endPoint Solid {
        translation 0.060000000397222086 -2.854388403688316e-06 -0.049997307331450705
        rotation -0.7059329460986922 0.7059355392145887 0.057564660046148367 3.026590670473263
        children [
          USE WHEEL
        ]
        name "solid(2)"
        boundingObject USE WHEEL
        physics Physics {
        }
      }
    }
    DEF BR_WHEEL HingeJoint {
      jointParameters HingeJointParameters {
        position 170.8800654398489
        anchor -0.06 0 -0.05
      }
      device [
        RotationalMotor {
          name "brwheel"
        }
      ]
      endPoint Solid {
        translation -0.05999999960326252 3.5958376826346768e-06 -0.050001570829962615
        rotation -0.4933302197063924 0.4933320318882277 -0.71641384732393 4.3849036499099405
        children [
          USE WHEEL
        ]
        name "solid(3)"
        boundingObject USE WHEEL
        physics Physics {
        }
      }
    }
    DEF DS_RIGHT DistanceSensor {
      translation -0.03 0 0.1
      rotation 0 1 0 -1.87079
      children [
        Shape {
          appearance PBRAppearance {
            baseColor 0.988235 0.913725 0.309804
            roughness 1
            metalness 0
          }
          geometry Box {
            size 0.01 0.01 0.01
          }
        }
      ]
      name "ds_right"
    }
    DEF DS_LEFT DistanceSensor {
      translation 0.03 0 0.1
      rotation 0 1 0 -1.27079
      children [
        Shape {
          appearance PBRAppearance {
            baseColor 0.988235 0.913725 0.309804
            roughness 1
            metalness 0
          }
          geometry Box {
            size 0.01 0.01 0.01
          }
        }
      ]
      name "ds_left"
    }
  ]
  name "team3_robot"
  boundingObject USE BODY
  physics Physics {
    density -1
    mass 1
  }
  controller "robot_control"
}
