#VRML_SIM R2020a utf8
WorldInfo {
}
Viewpoint {
  orientation -0.03432234506676366 0.9811367695180863 0.19024357053191523 2.7590946438124937
  position -1.0138297289930176 0.31125577760190953 0.6897009711926096
}
TexturedBackground {
}
TexturedBackgroundLight {
}
RectangleArena {
  floorSize 3.5 3.5
  wallThickness 0.02
  wallHeight 0.3
}
Robot {
  translation -1.23138 0.0397206 1.28743
  rotation 3.9115399986248e-06 0.9999999996484248 -2.6226899990779272e-05 2.84664
  children [
    GPS {
    }
    Camera {
      translation 0 0.03 0.085
      rotation 0 1 0 3.14159
      children [
        Shape {
          appearance PBRAppearance {
            baseColor 0 0 0
          }
          geometry Box {
            size 0.04 0.01 0.01
          }
        }
      ]
      name "camera0"
      width 100
      height 100
    }
    DEF BODY Shape {
      appearance PBRAppearance {
        baseColor 0.678431 0.498039 0.658824
        roughness 1
        metalness 0
      }
      geometry Box {
        size 0.1 0.05 0.2
      }
    }
    DEF TL_WHEEL HingeJoint {
      jointParameters HingeJointParameters {
        position 500.09571190081215
        anchor 0.06 0 0.05
      }
      device [
        RotationalMotor {
          name "tlwheel"
        }
      ]
      endPoint Solid {
        translation 0.059999999603073784 -2.85441713302989e-06 0.05000269263808757
        rotation -0.7059329956090296 0.7059355887073491 0.05756344592595712 3.0265930907113714
        children [
          DEF WHEEL Shape {
            appearance PBRAppearance {
              baseColor 0.203922 0.396078 0.643137
              roughness 1
              metalness 0
            }
            geometry Cylinder {
              height 0.02
              radius 0.04
              subdivision 24
            }
          }
        ]
        boundingObject USE WHEEL
        physics Physics {
        }
	linearVelocity 0.011619250889313251 -7.459452132703303e-08 -0.03827508208129862
        angularVelocity -0.9568816848067551 7.728232029795201e-06 -0.29047863003376956
      }
    }
    DEF TR_WHEEL HingeJoint {
      jointParameters HingeJointParameters {
        position 452.14101668453543
        anchor -0.06 0 0.05
      }
      device [
        RotationalMotor {
          name "trwheel"
        }
      ]
      endPoint Solid {
        translation -0.0600000003974106 3.595854379952e-06 0.04999842920827169
        rotation -0.4933293044325202 0.49333111663075313 -0.716415107847385 4.384905315914679
        children [
          USE WHEEL
        ]
        name "solid(1)"
        boundingObject USE WHEEL
        physics Physics {
        }
	linearVelocity 0.011619336347572671 5.411557786317642e-08 -0.03827536359283268
        angularVelocity -0.9568817074383845 7.728258296789388e-06 -0.29047863669185003
      }
    }
    DEF BL_WHEEL HingeJoint {
      jointParameters HingeJointParameters {
        position 500.0957365388898
        anchor 0.06 0 -0.05
      }
      device [
        RotationalMotor {
          name "blwheel"
        }
      ]
      endPoint Solid {
        translation 0.060000000397222086 -2.85438840368608e-06 -0.049997307331450705
        rotation -0.7059329460986924 0.7059355392145885 0.05756466004614837 3.026590670473263
        children [
          USE WHEEL
        ]
        name "solid(2)"
        boundingObject USE WHEEL
        physics Physics {
        }
	linearVelocity 0.011618953153786778 -5.419754986443827e-08 -0.038275172423012316
        angularVelocity -0.9568816936127185 7.733482246721763e-06 -0.2904786010135933
      }
    }
    DEF BR_WHEEL HingeJoint {
      jointParameters HingeJointParameters {
        position 452.14104124762804
        anchor -0.06 0 -0.05
      }
      device [
        RotationalMotor {
          name "brwheel"
        }
      ]
      endPoint Solid {
        translation -0.05999999960326252 3.595837682635492e-06 -0.050001570829962615
        rotation -0.49333021970639246 0.49333203188822755 -0.71641384732393 4.3849036499099405
        children [
          USE WHEEL
        ]
        name "solid(3)"
        boundingObject USE WHEEL
        physics Physics {
        }
	linearVelocity 0.01161903862800375 7.448856132703456e-08 -0.03827545398688044
        angularVelocity -0.956881716247988 7.733512633422913e-06 -0.29047860767468314
      }
    }
    DEF DS_RIGHT DistanceSensor {
      translation -0.03 0 0.1
      rotation 0 1 0 -1.8707853071795864
      children [
        Shape {
          appearance PBRAppearance {
            baseColor 0.988235 0.913725 0.309804
            roughness 1
            metalness 0
          }
          geometry Box {
            size 0.01 0.01 0.01
          }
        }
      ]
      name "ds_right"
      type "laser"
      aperture 0.01
    }
    DEF DS_LEFT DistanceSensor {
      translation 0.03 0 0.1
      rotation 0 1 0 -1.2707853071795858
      children [
        Shape {
          appearance PBRAppearance {
            baseColor 0.988235 0.913725 0.309804
            roughness 1
            metalness 0
          }
          geometry Box {
            size 0.01 0.01 0.01
          }
        }
      ]
      name "ds_left"
      type "laser"
      aperture 0.01
    }
  ]
  name "team3_robot"
  boundingObject USE BODY
  physics Physics {
    density -1
    mass 1
  }
  controller "robot_control"
}
