#VRML_SIM R2020a utf8
WorldInfo {
}
Viewpoint {
  orientation 0.013484902072138089 0.932617906734205 0.36061336283451095 3.194429880441243
  position 0.2651483281411744 3.6054869193428143 -3.9056383324351267
}
TexturedBackground {
}
TexturedBackgroundLight {
}
RectangleArena {
  floorSize 3.5 3.5
  wallThickness 0.02
  wallHeight 0.3
}
Robot {
  translation 1.52933 0.039721 -1.25373
  rotation -1.1055444151699807e-05 0.991229315534826 -0.13215310780355385 6.504228747735712e-08
  children [
    Camera {
      translation 0 0.03 0.085
      rotation 0 1 0 3.14159
      children [
        Shape {
          appearance PBRAppearance {
            baseColor 0 0 0
          }
          geometry Box {
            size 0.04 0.01 0.01
          }
        }
      ]
      name "camera0"
      width 100
      height 100
    }
    DEF BODY Shape {
      appearance PBRAppearance {
        baseColor 0.678431 0.498039 0.658824
        roughness 1
        metalness 0
      }
      geometry Box {
        size 0.1 0.05 0.2
      }
    }
    DEF WHEEL1 HingeJoint {
      jointParameters HingeJointParameters {
        position 26.591999983495768
        anchor 0.06 0 0.05
      }
      device [
        RotationalMotor {
          name "wheel1"
        }
      ]
      endPoint Solid {
        translation 0.06 0 0.05
        rotation 0.5546565855287673 -0.5546586228999096 0.6202498562453238 2.0312435703453864
        children [
          DEF WHEEL Shape {
            appearance PBRAppearance {
              baseColor 0.203922 0.396078 0.643137
              roughness 1
              metalness 0
            }
            geometry Cylinder {
              height 0.02
              radius 0.04
              subdivision 24
            }
          }
        ]
        boundingObject USE WHEEL
        physics Physics {
        }
      }
    }
    DEF WHEEL2 HingeJoint {
      jointParameters HingeJointParameters {
        position 26.591999984031904
        anchor -0.06 0 0.05
      }
      device [
        RotationalMotor {
          name "wheel2"
        }
      ]
      endPoint Solid {
        translation -0.06 0 0.05
        rotation 0.5546565856438845 -0.5546586230150272 0.6202498560394366 2.031243570642758
        children [
          USE WHEEL
        ]
        name "solid(1)"
        boundingObject USE WHEEL
        physics Physics {
        }
      }
    }
    DEF WHEEL3 HingeJoint {
      jointParameters HingeJointParameters {
        position 26.59199999031702
        anchor 0.06 0 -0.05
      }
      device [
        RotationalMotor {
          name "wheel3"
        }
      ]
      endPoint Solid {
        translation 0.06 0 -0.05
        rotation 0.5546565869934001 -0.5546586243645477 0.6202498536258274 2.031243574128838
        children [
          USE WHEEL
        ]
        name "solid(2)"
        boundingObject USE WHEEL
        physics Physics {
        }
      }
    }
    DEF WHEEL4 HingeJoint {
      jointParameters HingeJointParameters {
        position 26.59199999085316
        anchor -0.06 0 -0.05
      }
      device [
        RotationalMotor {
          name "wheel4"
        }
      ]
      endPoint Solid {
        translation -0.06 0 -0.05
        rotation 0.554656587108518 -0.5546586244796661 0.6202498534199388 2.031243574426212
        children [
          USE WHEEL
        ]
        name "solid(3)"
        boundingObject USE WHEEL
        physics Physics {
        }
      }
    }
    DEF DS_RIGHT DistanceSensor {
      translation -0.03 0 0.1
      rotation 0 1 0 -1.87079
      children [
        Shape {
          appearance PBRAppearance {
            baseColor 0.988235 0.913725 0.309804
            roughness 1
            metalness 0
          }
          geometry Box {
            size 0.01 0.01 0.01
          }
        }
      ]
      name "ds_right"
    }
    DEF DS_LEFT DistanceSensor {
      translation 0.03 0 0.1
      rotation 0 1 0 -1.27079
      children [
        Shape {
          appearance PBRAppearance {
            baseColor 0.988235 0.913725 0.309804
            roughness 1
            metalness 0
          }
          geometry Box {
            size 0.01 0.01 0.01
          }
        }
      ]
      name "ds_left"
    }
  ]
  boundingObject USE BODY
  physics Physics {
    density -1
    mass 1
  }
  controller "collision_avoidance"
}
