#VRML_SIM R2020a utf8
WorldInfo {
}
Viewpoint {
  orientation 0.1608762902585689 -0.9740132294610906 -0.15942725007795086 4.734062329791207
  position 1.2239780672925589 1.5352606201852725 1.1145826710406586
}
TexturedBackground {
}
TexturedBackgroundLight {
}
RectangleArena {
  floorSize 3.5 3.5
  wallThickness 0.02
  wallHeight 0.3
}
Robot {
  translation -1.4007233282509348 0.0397234449247195 0.4409882450588258
  rotation 9.738414646611087e-06 0.9999999999515801 1.415338076587048e-06 2.8469077675804844
  children [
    GPS {
    }
    Camera {
      translation 0 0.03 0.085
      rotation 0 1 0 3.14159
      children [
        Shape {
          appearance PBRAppearance {
            baseColor 0 0 0
          }
          geometry Box {
            size 0.04 0.01 0.01
          }
        }
      ]
      name "camera0"
      width 100
      height 100
    }
    DEF BODY Shape {
      appearance PBRAppearance {
        baseColor 0.678431 0.498039 0.658824
        roughness 1
        metalness 0
      }
      geometry Box {
        size 0.1 0.05 0.2
      }
    }
    DEF WHEEL1 HingeJoint {
      jointParameters HingeJointParameters {
        position 500.09571190081215
        anchor 0.06 0 0.05
      }
      device [
        RotationalMotor {
          name "wheel1"
        }
      ]
      endPoint Solid {
        translation 0.059999999603073784 -3.6628392003792008e-06 0.05000140769529094
        rotation 0.693334929200491 -0.6933374760118329 -0.19639200673166698 3.5294391457140057
        children [
          DEF WHEEL Shape {
            appearance PBRAppearance {
              baseColor 0.203922 0.396078 0.643137
              roughness 1
              metalness 0
            }
            geometry Cylinder {
              height 0.02
              radius 0.04
              subdivision 24
            }
          }
        ]
        boundingObject USE WHEEL
        physics Physics {
        }
        linearVelocity 0.011619250889313251 -7.459452132703303e-08 -0.03827508208129862
        angularVelocity -0.9568816848067551 7.728232029795201e-06 -0.29047863003376956
      }
    }
    DEF WHEEL2 HingeJoint {
      jointParameters HingeJointParameters {
        position 452.14101668453543
        anchor -0.06 0 0.05
      }
      device [
        RotationalMotor {
          name "wheel2"
        }
      ]
      endPoint Solid {
        translation -0.0600000003974106 -1.247153511650158e-06 0.04999627949418843
        rotation -0.13642387466528308 0.1364243757996593 0.9812119628851783 1.5897656370236284
        children [
          USE WHEEL
        ]
        name "solid(1)"
        boundingObject USE WHEEL
        physics Physics {
        }
        linearVelocity 0.011619336347572671 5.411557786317642e-08 -0.03827536359283268
        angularVelocity -0.9568817074383845 7.728258296789388e-06 -0.29047863669185003
      }
    }
    DEF WHEEL3 HingeJoint {
      jointParameters HingeJointParameters {
        position 500.0957365388898
        anchor 0.06 0 -0.05
      }
      device [
        RotationalMotor {
          name "wheel3"
        }
      ]
      endPoint Solid {
        translation 0.060000000397222086 -3.662854079780416e-06 -0.049998592343413424
        rotation 0.6933336713817644 -0.6933362182088033 -0.19640088759524027 3.529456247747853
        children [
          USE WHEEL
        ]
        name "solid(2)"
        boundingObject USE WHEEL
        physics Physics {
        }
        linearVelocity 0.011618953153786778 -5.419754986443827e-08 -0.038275172423012316
        angularVelocity -0.9568816936127185 7.733482246721763e-06 -0.2904786010135933
      }
    }
    DEF WHEEL4 HingeJoint {
      jointParameters HingeJointParameters {
        position 452.14104124762804
        anchor -0.06 0 -0.05
      }
      device [
        RotationalMotor {
          name "wheel4"
        }
      ]
      endPoint Solid {
        translation -0.05999999960326252 -1.2471141428179553e-06 -0.050003720519013
        rotation -0.1364120345199599 0.1364125356417619 0.9812152551595955 1.5897622823190858
        children [
          USE WHEEL
        ]
        name "solid(3)"
        boundingObject USE WHEEL
        physics Physics {
        }
        linearVelocity 0.01161903862800375 7.448856132703456e-08 -0.03827545398688044
        angularVelocity -0.956881716247988 7.733512633422913e-06 -0.29047860767468314
      }
    }
    DEF DS_RIGHT DistanceSensor {
      translation -0.03 0 0.1
      rotation 0 1 0 -1.8707853071795864
      children [
        Shape {
          appearance PBRAppearance {
            baseColor 0.988235 0.913725 0.309804
            roughness 1
            metalness 0
          }
          geometry Box {
            size 0.01 0.01 0.01
          }
        }
      ]
      name "ds_right"
      type "laser"
      aperture 0.01
    }
    DEF DS_LEFT DistanceSensor {
      translation 0.03 0 0.1
      rotation 0 1 0 -1.2707853071795858
      children [
        Shape {
          appearance PBRAppearance {
            baseColor 0.988235 0.913725 0.309804
            roughness 1
            metalness 0
          }
          geometry Box {
            size 0.01 0.01 0.01
          }
        }
      ]
      name "ds_left"
      type "laser"
      aperture 0.01
    }
  ]
  boundingObject USE BODY
  physics Physics {
    density -1
    mass 1
  }
  controller "collision_avoidance"
  linearVelocity 0.011619866092676368 -1.1074834987664338e-06 -0.03827764424857017
  angularVelocity 1.2048598655850582e-05 -1.1069336896194463e-05 -4.04109948023927e-05
}
